<?xml version="1.0" encoding="utf-8"?>
<!-- This URDF was automatically created by SolidWorks to URDF Exporter! Originally created by Stephen Brawner (brawner@gmail.com) 
     Commit Version: 1.6.0-4-g7f85cfe  Build Version: 1.6.7995.38578
     For more information, please see http://wiki.ros.org/sw_urdf_exporter -->
<robot
  name="comobot">
  <link
    name="base_link">
    <inertial>
      <origin
        xyz="-0.0178929341348187 0.00617227578586497 0.0649453185184938"
        rpy="0 0 0" />
      <mass
        value="9.3352790819242" />
      <inertia
        ixx="0.0628143238612103"
        ixy="-6.93593528960888E-05"
        ixz="0.000683337399392882"
        iyy="0.0291145257808782"
        iyz="-3.57527382468155E-11"
        izz="0.0825233943729038" />
    </inertial>
    <visual>
      <origin
        xyz="0 0 0"
        rpy="0 0 0" />
      <geometry>
        <mesh
          filename="package://comobot/meshes/base_link.STL" />
      </geometry>
      <material
        name="">
        <color
          rgba="0.752941176470588 0.752941176470588 0.752941176470588 1" />
      </material>
    </visual>
    <collision>
      <origin
        xyz="0 0 0"
        rpy="0 0 0" />
      <geometry>
        <mesh
          filename="package://comobot/meshes/base_link.STL" />
      </geometry>
    </collision>
  </link>
  <link
    name="wheel_R">
    <inertial>
      <origin
        xyz="-0.00025939 -0.082206 -0.00044757"
        rpy="0 0 0" />
      <mass
        value="0.65908" />
      <inertia
        ixx="0.0010518"
        ixy="-1.0673E-12"
        ixz="2.3608E-07"
        iyy="0.0018786"
        iyz="-6.4787E-08"
        izz="0.0010521" />
    </inertial>
    <visual>
      <origin
        xyz="0 0 0"
        rpy="0 0 0" />
      <geometry>
        <mesh
          filename="package://comobot/meshes/wheel_R.STL" />
      </geometry>
      <material
        name="">
        <color
          rgba="0.75294 0.75294 0.75294 1" />
      </material>
    </visual>
    <collision>
      <origin
        xyz="0 0 0"
        rpy="0 0 0" />
      <geometry>
        <mesh
          filename="package://comobot/meshes/wheel_R.STL" />
      </geometry>
    </collision>
  </link>
  <joint
    name="joint_R"
    type="continuous">
    <origin
      xyz="0.1 -0.16933 0.036922"
      rpy="0 0 0" />
    <parent
      link="base_link" />
    <child
      link="wheel_R" />
    <axis
      xyz="0 1 0" />
  </joint>
  <link
    name="wheel_L">
    <inertial>
      <origin
        xyz="0.00025939 0.082206 -0.00044757"
        rpy="0 0 0" />
      <mass
        value="0.65908" />
      <inertia
        ixx="0.0010518"
        ixy="-1.0673E-12"
        ixz="-2.3608E-07"
        iyy="0.0018786"
        iyz="6.4787E-08"
        izz="0.0010521" />
    </inertial>
    <visual>
      <origin
        xyz="0 0 0"
        rpy="0 0 0" />
      <geometry>
        <mesh
          filename="package://comobot/meshes/wheel_L.STL" />
      </geometry>
      <material
        name="">
        <color
          rgba="0.75294 0.75294 0.75294 1" />
      </material>
    </visual>
    <collision>
      <origin
        xyz="0 0 0"
        rpy="0 0 0" />
      <geometry>
        <mesh
          filename="package://comobot/meshes/wheel_L.STL" />
      </geometry>
    </collision>
  </link>
  <joint
    name="joint_L"
    type="continuous">
    <origin
      xyz="0.1 0.18167 0.036922"
      rpy="0 0 0" />
    <parent
      link="base_link" />
    <child
      link="wheel_L" />
    <axis
      xyz="0 1 0" />
  </joint>
  
  <!-- <gazebo>
    <plugin name="gazebo_ros_control" filename="libgazebo_ros_control.so">
    <robotNamespace>/</robotNamespace>
    </plugin>
  </gazebo> -->

</robot>